<?xml version="1.0" encoding="UTF-8"?>
<!-- Generated by org.testng.reporters.JUnitReportReporter -->
<testsuite name="com.qtpselenium.rediff.hybrid.testcases.portfoliosuite.LoginTest" tests="1" time="28.518" ignored="0" failures="0" timestamp="26 Sep 2018 22:23:32 GMT" skipped="0" hostname="DESKTOP-PKMC2016" errors="1">
  <testcase name="loginTest" time="28.518" classname="com.qtpselenium.rediff.hybrid.testcases.portfoliosuite.LoginTest">
    <error type="java.lang.reflect.InvocationTargetException">
      <![CDATA[java.lang.reflect.InvocationTargetException
	at sun.reflect.NativeMethodAccessorImpl.invoke0(Native Method)
	at sun.reflect.NativeMethodAccessorImpl.invoke(Unknown Source)
	at sun.reflect.DelegatingMethodAccessorImpl.invoke(Unknown Source)
	at java.lang.reflect.Method.invoke(Unknown Source)
	at com.qtpselenium.rediff.hybrid.driver.DriverScript.executeKeywords(DriverScript.java:47)
	at com.qtpselenium.rediff.hybrid.testcases.portfoliosuite.LoginTest.loginTest(LoginTest.java:25)
	at sun.reflect.NativeMethodAccessorImpl.invoke0(Native Method)
	at sun.reflect.NativeMethodAccessorImpl.invoke(Unknown Source)
	at sun.reflect.DelegatingMethodAccessorImpl.invoke(Unknown Source)
	at java.lang.reflect.Method.invoke(Unknown Source)
	at org.testng.internal.MethodInvocationHelper.invokeMethod(MethodInvocationHelper.java:104)
	at org.testng.internal.Invoker.invokeMethod(Invoker.java:645)
	at org.testng.internal.Invoker.invokeTestMethod(Invoker.java:851)
	at org.testng.internal.Invoker.invokeTestMethods(Invoker.java:1177)
	at org.testng.internal.TestMethodWorker.invokeTestMethods(TestMethodWorker.java:129)
	at org.testng.internal.TestMethodWorker.run(TestMethodWorker.java:112)
	at org.testng.TestRunner.privateRun(TestRunner.java:756)
	at org.testng.TestRunner.run(TestRunner.java:610)
	at org.testng.SuiteRunner.runTest(SuiteRunner.java:387)
	at org.testng.SuiteRunner.runSequentially(SuiteRunner.java:382)
	at org.testng.SuiteRunner.privateRun(SuiteRunner.java:340)
	at org.testng.SuiteRunner.run(SuiteRunner.java:289)
	at org.testng.SuiteRunnerWorker.runSuite(SuiteRunnerWorker.java:52)
	at org.testng.SuiteRunnerWorker.run(SuiteRunnerWorker.java:86)
	at org.testng.TestNG.runSuitesSequentially(TestNG.java:1293)
	at org.testng.TestNG.runSuitesLocally(TestNG.java:1218)
	at org.testng.TestNG.runSuites(TestNG.java:1133)
	at org.testng.TestNG.run(TestNG.java:1104)
	at org.testng.remote.AbstractRemoteTestNG.run(AbstractRemoteTestNG.java:132)
	at org.testng.remote.RemoteTestNG.initAndRun(RemoteTestNG.java:236)
	at org.testng.remote.RemoteTestNG.main(RemoteTestNG.java:81)
Caused by: java.lang.AssertionError: The following asserts failed:
	Object Not Found username_id
	at org.testng.asserts.SoftAssert.assertAll(SoftAssert.java:43)
	at com.qtpselenium.rediff.hybrid.keywords.GenericKeywords.reportFailure(GenericKeywords.java:424)
	at com.qtpselenium.rediff.hybrid.keywords.GenericKeywords.getObject(GenericKeywords.java:376)
	at com.qtpselenium.rediff.hybrid.keywords.AppKeywords.login(AppKeywords.java:34)
	... 31 more
]]>
    </error>
  </testcase> <!-- loginTest -->
</testsuite> <!-- com.qtpselenium.rediff.hybrid.testcases.portfoliosuite.LoginTest -->
